Workbook
Name TotalWeekRespondents: 'Аналитика'!$B$10
Name CurSprint: 'Аналитика'!$B$1

Sheet RawData
A1: timestamp | B1: session_id | C1: tg_id | D1: week | E1: group_id | F1: cubes_reactive | G1: cubes_proactive | H1: cubes_operational | I1: cubes_pool | J1: satisfaction | K1: representative | L1: work_life | M1: pss_1 | N1: pss_2 | O1: pss_3 | P1: pss_4 | Q1: takeaway | R1: comment | S1: time_total | T1: device_type | U1: Фактор дистресса | V1: Фактор совладания | W1: Воспринимаемый стресс
A2: 46208.376 | B2: 5501a13245b9a5b2133ed7b01a73fd31 | C2: artsm92 | D2: 0 | E2: 🔥%20Огоньки%20(ДС%202026q3) | F2: 4 | G2: 2 | H2: 0 | I2: 0 | J2: 4 | K2: -1 | L2: 1 | M2: 3 | N2: 3 | O2: 1 | P2: 3 | Q2: - одна задача в один момент времени, отключать уведомления в чатах где постоянно тегают - формулировка целей важна и размышления на тему где я сейчас | S2: 196 | T2: mobile | U2: {=M2:M642+P2:P642} -> 6 | V2: {=N2:N642+O2:O642} -> 4 | W2: {=U2:U642-V2:V642+8} -> 10
A3: 46208.417 | B3: b6d79df46cbaae1c89fa5ccc891b2b75 | C3: unfreeshooter | D3: 0 | E3: 🔥 Огоньки (ДС 2026q3) | F3: 3 | G3: 1 | H3: 2 | I3: 0 | J3: 6 | K3: -2 | L3: 0 | M3: 1 | N3: 3 | O3: 2 | P3: 1 | Q3: если делать и потом аналитить - почти все срабатывает на мне из практик. а если аналитить, а потом делать - делать будет нечего: все воспринимается лишь В ТЕОРИИ | R3: не очень показателен п2 "Насколько прошедшая неделя была похожа на ваш обычный режим работы?*" для меня: я из Севастополя, у нас внезапные отключения ЭЭ, что сильно влияет на формат работы. ну и пункты дальше тоже в разрезе проблем локальных с бензом и эл-вом/водой (пока только с ними)- все по фактам | S3: 736 | T3: desktop | U3: 2 | V3: 5 | W3: 5
A4: 46208.421 | B4: 1dd388c2279277f99a769060a5ed92df | C4: chernykh_irina | D4: 0 | E4: 💥%20Искорки%20(ДС%202026q3) | F4: 0 | G4: 2 | H4: 4 | I4: 0 | J4: 6 | K4: 1 | L4: 1 | M4: 0 | N4: 4 | O4: 4 | P4: 1 | Q4: Немножко почитала задачки и цели ребят на доске практики и поняла, что у меня в принципе нет опасений в жизни. Мои задачки все или рутинные или те, которые ведут меня к целям. По отдыху тоже интуитивно распределяю всякие классные активности, единственное в течение дня работаю и совсем не отдыхаю. Уже нашла пилатес-стулию рядом с работой, вот вернусь с командировки мечты и начну ходить по средам в обед на пилатес. И хочу потихоньку внедрять помидорки с отдыхом между ними и ретроспективу с командой по рабочим задачкам . | R4: Есть ощущение некоторой сумбурности в части просматриваемых видео. Понятно, что у вас уже накоплен багаж и одно и то же переснимать не сильно эффективно. Но например, ответы на вопросы с какой-то практики: Максим говорит про улитки так, что я уже должна быть сильно в теме, а мы ж ещё нигде не обсуждали их ☹️ На самой практике я не поняла почему до докопались с моей задачей «запросить документы для учебы», которую я привязала к цели «я настроила бизнес-процессы». Это же первый шажок к тому, чтобы научиться настраивать грамотно бизнес-процессы. Есть тут некоторое недопонимание, что за цель тогда должна быть, какой масштаб? Понимаю, что сложно выслушать все тройки, но ребята же могут просто не так понять и уйти в демагогию при обсуждении чьей-то цели. Кажется, что стоит делать акцент на длине чтобычтотора и вообще на то, что надо именно через «чтобы что» связывать задачу с целью. И рандомно выбирать хотя бы три таких связки для разбора под присмотром Максима не по комнатам, а при всё честнОм народе 🤗 | S4: 1074 | T4: mobile | U4: 1 | V4: 8 | W4: 1
A5: 46208.422 | B5: 4a30073f1ead1ba55d61a0be343d0577 | C5: Garikos8 | D5: 0 | E5: 🔥 Огоньки (ДС 2026q3) | F5: 3 | G5: 2 | H5: 1 | I5: 0 | J5: 6 | K5: 1 | L5: 1 | M5: 1 | N5: 3 | O5: 3 | P5: 1 | Q5: Мало составить план, надо уметь и двигаться по нему. | S5: 194 | T5: mobile | U5: 2 | V5: 6 | W5: 4
A6: 46208.433 | B6: a28815f6be6b96080aaa10769c623798 | C6: i1024i | D6: 0 | E6: 🌟%20Звёздочки%20(ДС%202026q3) | F6: 2 | G6: 3 | H6: 1 | I6: 0 | J6: 5 | K6: 1 | L6: 2 | M6: 2 | N6: 3 | O6: 2 | P6: 2 | Q6: Нужно планировать отдых, заранее определиться, как я буду отдыхать и использовать свободное время | S6: 116 | T6: mobile | U6: 4 | V6: 5 | W6: 7
A7: 46208.435 | B7: 4a5c4304337932162d21dade1831f645 | C7: tnikotyan | D7: 0 | E7: 💥 Искорки (ДС 2026q3) | F7: 4 | G7: 1 | H7: 1 | I7: 0 | J7: 4 | K7: -1 | L7: 1 | M7: 3 | N7: 2 | O7: 2 | P7: 3 | S7: 118 | T7: mobile | U7: 6 | V7: 4 | W7: 10
A8: 46208.436 | B8: 3de1e7bf0e4c2263132190427bb172e7 | C8: nvkoy | D8: 0 | E8: 🌟 Звёздочки (ДС 2026q3) | F8: 1 | G8: 4 | H8: 1 | I8: 0 | J8: 5 | K8: 1 | L8: 1 | M8: 1 | N8: 3 | O8: 3 | P8: 1 | Q8: "Чтобы что" сильно помогает избавиться от лишнего и расставить реальные приоритеты | R8: Вы лучшие! Спасибо! :) | S8: 185 | T8: desktop | U8: 2 | V8: 6 | W8: 4
A9: 46208.461 | B9: 4ba89f712442ebd55f3f6b203be24be0 | C9: dimisi | D9: 0 | E9: 💥 Искорки (ДС 2026q3) | F9: 1 | G9: 1 | H9: 2 | I9: 2 | J9: 7 | K9: 2 | L9: -2 | M9: 3 | N9: 3 | O9: 3 | P9: 4 | Q9: Отдыхать - крута! | S9: 133 | T9: desktop | U9: 7 | V9: 6 | W9: 9
A10: 46208.476 | B10: 98c4160f00a06c6698f9b03478083c04 | C10: oakimov | D10: 0 | E10: 🌟 Звёздочки (ДС 2026q3) | F10: 2 | G10: 0 | H10: 4 | I10: 0 | J10: 3 | K10: 1 | L10: 1 | M10: 2 | N10: 3 | O10: 3 | P10: 1 | Q10: Отдых - неотъемлемая часть грамотного труда | S10: 127 | T10: mobile | U10: 3 | V10: 6 | W10: 5
A11: 46208.482 | B11: 4bf2f7e9a7089a54f51634223dde8ef9 | C11: DarkJewel | D11: 0 | E11: 🌟 Звёздочки (ДС 2026q3) | F11: 1 | G11: 1 | H11: 2 | I11: 2 | J11: 6 | K11: 1 | L11: -2 | M11: 4 | N11: 1 | O11: 2 | P11: 4 | Q11: Читать художественные книги - мой вариант отдыха. | R11: Тяжёлая неделя, сделал очень мало. Ресурс в основном потрачен на поддержание жизни в тушке и на дохрена тревожных мыслей. НО! меня на этой неделе нашла работа, в понедельник выхожу на первую смену. | S11: 273 | T11: mobile | U11: 8 | V11: 3 | W11: 13
A12: 46208.54 | B12: a013009f551579acc6d31ae0fd2ffb29 | C12: fyodor5 | D12: 0 | E12: 💥 Искорки (ДС 2026q3) | F12: 1 | G12: 0 | H12: 1 | I12: 4 | J12: 2 | K12: -1 | L12: 0 | M12: 2 | N12: 3 | O12: 2 | P12: 0 | Q12: Мне необходимо внедрять рутины для фокуса на важных задачах для их выполнения, иначе я просто не сажусь их выполнять и разбираться. | S12: 150 | T12: desktop | U12: 2 | V12: 5 | W12: 5
A13: 46208.548 | B13: 950e34770b251536f8703a5140c506a3 | C13: n_Set | D13: 0 | E13: 💥 Искорки (ДС 2026q3) | F13: 0 | G13: 0 | H13: 0 | I13: 6 | J13: 4 | K13: 1 | L13: 1 | M13: 4 | N13: 3 | O13: 4 | P13: 3 | Q13: что давно забыл что мне именно интересно , так как часто перегружал себя работой, и когда приходит пора др я оч долго думаю чего бы я хотел, чаще говорю у меня все есть давайте деньгами | S13: 118 | T13: desktop | U13: 7 | V13: 7 | W13: 8
A14: 46208.554 | B14: 7bbad278ff70c5aa5f60086de71d2323 | C14: anna_metel87 | D14: 0 | E14: 🔥 Огоньки (ДС 2026q3) | F14: 1 | G14: 2 | H14: 3 | I14: 0 | J14: 6 | K14: 3 | L14: 0 | M14: 2 | N14: 3 | O14: 3 | P14: 0 | Q14: Из практики "чтобычтотор" - пожалуй, сам факт сформулированных целей. Из книги "Путь джедая" - что работать над зеленой задачей надо 1м делом за день и в любом состоянии и обстоятельствах, если хочешь прогресс. | R14: Вопрос: если задача понятна "обезьяне", но я все равно не хочу ее делать и поэтому откладываю - как мне решить эту проблему? По-хорошему, да, надо делегировать, это просто "не моя" задача, она не приближает меня ни к чему. Но я не могу ее спихнуть, это часть моих рабочих обязанностей, она недостаточна для найма целого человека (опять же NDA, чувствительные данные) и ее невозможно автоматизировать (там все что можно автоматизировано, мне финально просмотреть и каждый раз через боль🤪😁). | S14: 1611 | T14: mobile | U14: 2 | V14: 6 | W14: 4
A15: 46208.612 | B15: de27f4ae585a5b80d653f2d00f5d3feb | C15: victor_goriunov | D15: 0 | E15: 🌟 Звёздочки (ДС 2026q3) | F15: 2 | G15: 3 | H15: 1 | I15: 0 | J15: 6 | K15: 2 | L15: 2 | M15: 1 | N15: 3 | O15: 3 | P15: 2 | Q15: Via negativa. Не столько добавлять упражнения для отдыха, сколько НЕ делать лишнего. Есть предощущение, что текущий курс может сработать. | S15: 345 | T15: desktop | U15: 3 | V15: 6 | W15: 5
A16: 46208.621 | B16: 85727bd551d9a4576689d6beae69dee6 | C16: PalaVistas | D16: 0 | E16: 💥%20Искорки%20(ДС%202026q3) | F16: 2 | G16: 1 | H16: 1 | I16: 2 | J16: 2 | K16: -1 | L16: 0 | M16: 3 | N16: 2 | O16: 1 | P16: 3 | S16: 180 | T16: mobile | U16: 6 | V16: 3 | W16: 11
A17: 46208.63 | B17: 9ec07e9263d0206f098f5f4af3bf16f0 | C17: PolyakovaAR | D17: 0 | E17: 🌟 Звёздочки (ДС 2026q3) | F17: 0 | G17: 0 | H17: 0 | I17: 6 | J17: 4 | K17: 0 | L17: 0 | M17: 1 | N17: 3 | O17: 2 | P17: 2 | Q17: мне очень тяжело заставлять себя читать правила всех этих опросников тетрадей и прочего я не вижу в них ценности | S17: 125 | T17: desktop | U17: 3 | V17: 5 | W17: 6
A18: 46208.632 | B18: c493b0688a2309f5eb2a18ee2a9b24be | C18: kiralary | D18: 0 | E18: ☀️%20Лучики%20(ДС%202026q3) | F18: 2 | G18: 1 | H18: 2 | I18: 1 | J18: 6 | K18: 2 | L18: 1 | M18: 1 | N18: 3 | O18: 3 | P18: 1 | Q18: Можно отдыхать каждый день! Даже пять минут отдыха уже что-то значат. | R18: Спасибо за рекомендацию Анны Обуховой. Теперь слушаю её в свободное время | S18: 9401 | T18: mobile | U18: 2 | V18: 6 | W18: 4
A19: 46208.637 | B19: ac10cbb802efa6b77ccf890acaa30db2 | C19: basilmiron | D19: 0 | E19: ☀️ Лучики (ДС 2026q3) | F19: 2 | G19: 3 | H19: 1 | I19: 0 | J19: 5 | K19: 1 | L19: -2 | M19: 3 | N19: 2 | O19: 0 | P19: 1 | Q19: Хочешь чему-то научиться -- попробуй научить этому других. | R19: Хотелось бы большей вовлечённости участников -- пока что чат нашей группы в телеге потихоньку зарастает тиной и покрывается ряской 🥲 | S19: 192 | T19: desktop | U19: 4 | V19: 2 | W19: 10
A20: 46208.642 | B20: 4b2d6b105edba5b16e2937cd6c02300a | C20: LESNYAKSERGEY | D20: 0 | E20: ☀️ Лучики (ДС 2026q3) | F20: 3 | G20: 0 | H20: 1 | I20: 2 | J20: 2 | K20: 0 | L20: 2 | M20: 2 | N20: 2 | O20: 1 | P20: 3 | S20: 164 | T20: desktop | U20: 5 | V20: 3 | W20: 10
A21: 46208.674 | B21: 845c8863cec29d0b32eae38855a8d42c | C21: Olegkim0 | D21: 0 | E21: ☀️ Лучики (ДС 2026q3) | F21: 3 | G21: 3 | H21: 0 | I21: 0 | J21: 5 | K21: 2 | L21: 3 | M21: 3 | N21: 2 | O21: 3 | P21: 1 | S21: 81 | T21: mobile | U21: 4 | V21: 5 | W21: 7
A22: 46208.691 | B22: 4cb2ef87d139c0e0271a8281c30790cd | C22: shaklein_e | D22: 0 | E22: 🔥%20Огоньки%20(ДС%202026q3) | F22: 1 | G22: 3 | H22: 2 | I22: 0 | J22: 5 | K22: 1 | L22: 0 | M22: 1 | N22: 4 | O22: 3 | P22: 0 | Q22: Что живу содержательную и интересную жизнь | S22: 150 | T22: mobile | U22: 1 | V22: 7 | W22: 2
A23: 46208.704 | B23: 9ef2e0fec483bfa493bd00e2ce84f744 | C23: petrovgenq | D23: 0 | E23: чат | F23: 3 | G23: 0 | H23: 3 | I23: 0 | J23: 1 | K23: -3 | L23: 3 | M23: 3 | N23: 3 | O23: 2 | P23: 2 | Q23: Отдых это важно | R23: Спасибо за то, что вы делаете | S23: 302 | T23: desktop | U23: 5 | V23: 5 | W23: 8
A24: 46208.715 | B24: d81a06a6395aec67d6cf869068999809 | C24: elpaev | D24: 0 | E24: ☀️ Лучики (ДС 2026q3) | F24: 2 | G24: 1 | H24: 3 | I24: 0 | J24: 5 | K24: 0 | L24: -2 | M24: 2 | N24: 2 | O24: 3 | P24: 1 | S24: 145 | T24: mobile | U24: 3 | V24: 5 | W24: 6
A25: 46208.873 | B25: 3b2198a73517fc391fa71e547fb26be1 | C25: dhbdt | D25: 0 | E25: 🌟 Звёздочки (ДС 2026q3) | F25: 3 | G25: 1 | H25: 1 | I25: 1 | J25: 5 | K25: -1 | L25: 1 | M25: 1 | N25: 3 | O25: 3 | P25: 1 | Q25: Даже если прямо сейчас я не могу воспользоваться всеми накопленными знаниями/навыками, это не делает их бесполезными И это повод сфокусироваться не на приобретении новых, а на распаковывании этого багажа силы | S25: 527 | T25: mobile | U25: 2 | V25: 6 | W25: 4
A26: 46208.904 | B26: 3635adc097205b514c8c7bd033e85d97 | C26: grigory_sam | D26: 0 | E26: ☀️ Лучики (ДС 2026q3) | F26: 2 | G26: 2 | H26: 1 | I26: 1 | J26: 6 | K26: -2 | L26: 2 | M26: 2 | N26: 2 | O26: 2 | P26: 2 | Q26: Короткая версия - Парадоксально, что на неделе посвященной Отдыху я херачил как не в себя. Но постоянно держал в голове мысль о важности отдыха. Да и почувствовать эту важность получилось, когда энергию приходилось выскребать с самого дна. Для отдыха как будто бы не оставалось времени (там очень страшная красная задача, точнее проект). Так вот, удалось столкнуть жесткое пренебреждение отдыхом и осознание абсолютной необходимости в нём. И я нашел один из потерянных ключей к своей продуктивности - чрезвычайно важны понятные и конкретные мои собственные цели. Я теряю время в течение рабочего дня, потому что не могу сконцентрироваться и сделать даже что-то обезьянопонятное. Но как только у меня в трекере появилась связь задач с целями - это был настоящий буст. Инсайт сугубо личный. Есть немало людей, которые хорошо формулируют и представляют свои цели. Иметь кристально ясную, мою собственную, личную цель (которая ничем не оправдана, типа работы) - очень помогает быть эффективнее, даже когда энергии почти нет. | R26: Искренняя благодарность. Отдельно приятно, что у курса так хорошо развилась коммьюнити-составляющая, это здорово. | S26: 1370 | T26: desktop | U26: 4 | V26: 4 | W26: 8
A27: 46208.957 | B27: e30b3be204d2fa9d7cc26eec59e7108d | C27: Katrinacarrotss | D27: 0 | E27: 💥 Искорки (ДС 2026q3) | F27: 2 | G27: 1 | H27: 3 | I27: 0 | J27: 5 | K27: -1 | L27: 1 | M27: 4 | N27: 2 | O27: 1 | P27: 4 | Q27: Мне нужно включить в свою жизнь отдых. ежедневный, еженедельный, ежемесячный, ежегодный. Я на правильном пути | R27: Здорово, что есть такой проект и он помогает людям улучшать жизнь | S27: 210 | T27: desktop | U27: 8 | V27: 3 | W27: 13
A28: 46209.336 | B28: 172a6a56331da047b00273e32207d689 | C28: sp190819 | D28: 0 | E28: чат | F28: 2 | G28: 1 | H28: 1 | I28: 2 | J28: 5 | K28: 1 | L28: 0 | M28: 3 | N28: 3 | O28: 1 | P28: 3 | Q28: 1. То, что в списке моих текущих задач практически нет задач, которые напрямую бы вели меня к моим целям, 2. То, что отдых можно и нужно планировать и организовывать как сам отдых, так и время для него... | R28: Вижу большую ценность в практике, вовлечен скорее на минималках, то есть делаю необходимое почти в срок, меня это устраивает... | S28: 331 | T28: desktop | U28: 6 | V28: 4 | W28: 10
A29: 46209.355 | B29: eb27c285c0911029f321c56039b04f93 | C29: mitgych | D29: 0 | E29: 💥 Искорки (ДС 2026q3) | F29: 2 | G29: 2 | H29: 2 | I29: 0 | J29: 4 | K29: 0 | L29: 2 | M29: 3 | N29: 2 | O29: 1 | P29: 3 | Q29: джедайский старт - мой шанс выбраться из рутины. | S29: 48724 | T29: desktop | U29: 6 | V29: 3 | W29: 11
A30: 46209.389 | B30: 5dde0de6f7bf2f7bd95fdcf716c9debe | C30: tigrenok_katiel | D30: 0 | E30: ☀️ Лучики (ДС 2026q3) | F30: 2 | G30: 1 | H30: 2 | I30: 1 | J30: 6 | K30: 3 | L30: 1 | M30: 2 | N30: 3 | O30: 3 | P30: 2 | S30: 88 | T30: desktop | U30: 4 | V30: 6 | W30: 6
A31: 46209.448 | B31: 96ec63d4dab19babc9358e877514b445 | C31: chillimpostor | D31: 0 | E31: ☀️ Лучики (ДС 2026q3) | F31: 2 | G31: 1 | H31: 2 | I31: 1 | J31: 5 | K31: 0 | L31: 2 | M31: 3 | N31: 2 | O31: 2 | P31: 3 | Q31: Главные идеи/выводы по теме недели. - Важно благополучие, работа и дела не цель, а средство. - Самоорганизация и планирование, системы и техники, нужны чтобы жить лучше, а не делать больше. - Отдых и досуг не награда, а забота о себе. Без них нет сил и желания, только истощение, выгорание и саботаж. | S31: 219 | T31: mobile | U31: 6 | V31: 4 | W31: 10
A32: 46209.493 | B32: 995b4fba758836832c8b3c807d0dd941 | C32: dmtszv | D32: 0 | E32: ☀️ Лучики (ДС 2026q3) | F32: 1 | G32: 1 | H32: 2 | I32: 2 | J32: 5 | K32: 0 | L32: 0 | M32: 1 | N32: 3 | O32: 3 | P32: 1 | Q32: Мне необходимо чётко разделять отдых и работу и не жертвовать первым в пользу второго. | R32: Вы мне нравитесь ;) | S32: 360 | T32: mobile | U32: 2 | V32: 6 | W32: 4
A33: 46209.686 | B33: 76818b0bb39c8fde93db3fe7c435c371 | C33: baikova_f | D33: 0 | E33: чат | F33: 1 | G33: 1 | H33: 1 | I33: 3 | J33: 5 | K33: 1 | L33: -3 | M33: 3 | N33: 3 | O33: 1 | P33: 2 | Q33: Я не умею отдыхать. Срочно учиться отдыхать! Искать радости для ежедневного и еженедельного отдыха. | R33: 🫶 | S33: 596 | T33: desktop | U33: 5 | V33: 4 | W33: 9
A34: 46209.914 | B34: 07aa1418f1cf5886048222d19aed58a8 | C34: Ninanikolavna | D34: 0 | E34: 🌟 Звёздочки (ДС 2026q3) | F34: 2 | G34: 2 | H34: 2 | I34: 0 | J34: 6 | K34: 2 | L34: 1 | M34: 3 | N34: 1 | O34: 1 | P34: 2 | Q34: Что отдых в шкале важности должен быть наравне с работой. А не на последнем месте, как у меня. | R34: Спасибо, мне у вас нравится:) | S34: 438 | T34: mobile | U34: 5 | V34: 2 | W34: 11
A35: 46209.964 | B35: 39de27188ff28233cab652101f1324b2 | C35: oNZ7xpXJfrkasyb2enBr | D35: 0 | E35: 🌟 Звёздочки (ДС 2026q3) | F35: 0 | G35: 0 | H35: 2 | I35: 4 | J35: 4 | K35: 1 | L35: -3 | M35: 0 | N35: 3 | O35: 3 | P35: 1 | Q35: Укрепился в мысли, что без качественного целеполагания эффективно тратить мыслетопливо не получится. А для целей нужно сформулировать идентичность. В свою очередь для определения идентичности, чтобы хватило сил, сначала нужно научиться отдыхать (на этой формулировке обезьяну хватил Кондратий). | S35: 656 | T35: desktop | U35: 1 | V35: 6 | W35: 3
A36: 46210.319 | B36: b5d32088b1e337361fdc777e91d56681 | C36: smart_roger | D36: 0 | E36: 🔥 Огоньки (ДС 2026q3) | F36: 2 | G36: 1 | H36: 3 | I36: 0 | J36: 4 | K36: 1 | L36: -1 | M36: 2 | N36: 3 | O36: 2 | P36: 3 | S36: 46 | T36: mobile | U36: 5 | V36: 5 | W36: 8
A37: 46210.333 | B37: 93d360291e11d9552e18d5338e87b754 | C37: zhilabylamasha | D37: 0 | E37: 💥%20Искорки%20(ДС%202026q3) | F37: 1 | G37: 2 | H37: 1 | I37: 2 | J37: 5 | K37: 1 | L37: 1 | M37: 1 | N37: 3 | O37: 4 | P37: 1 | Q37: Если есть время, нужно в него «попадать», иначе потом вернуться к задаче будет сложно. | S37: 98 | T37: mobile | U37: 2 | V37: 7 | W37: 3
A38: 46210.46 | B38: 1abd48cde723ee4585125f117925cfa7 | C38: TaM_tAm_666 | D38: 0 | E38: ☀️ Лучики (ДС 2026q3) | F38: 0 | G38: 1 | H38: 4 | I38: 1 | J38: 5 | K38: 1 | L38: -3 | M38: 1 | N38: 3 | O38: 2 | P38: 1 | Q38: Нужно регулярно ходить в отпуска. Кайфовый отпуск - залог хорошего настроения. | S38: 410 | T38: desktop | U38: 2 | V38: 5 | W38: 5
A39: 46210.482 | B39: e09a43a51e3b97f4d10cd33ed5c51f75 | C39: OlegLyukshin | D39: 0 | E39: ☀️%20Лучики%20(ДС%202026q3) | F39: 3 | G39: 1 | H39: 2 | I39: 0 | J39: 3 | K39: 0 | L39: -1 | M39: 2 | N39: 1 | O39: 2 | P39: 2 | S39: 70 | T39: mobile | U39: 4 | V39: 3 | W39: 9
A40: 46210.515 | B40: 456b8de36dc43a6c82a07736d53d3379 | C40: komalexei | D40: 0 | E40: 💥 Искорки (ДС 2026q3) | F40: 3 | G40: 1 | H40: 2 | I40: 0 | J40: 5 | K40: 1 | L40: 0 | M40: 3 | N40: 3 | O40: 2 | P40: 2 | Q40: Важно находить время для отдыха который тебя порадует или просто отключиться от информационного шума и прогуляться 10-15 минут наедине с самим собой. | S40: 474 | T40: mobile | U40: 5 | V40: 5 | W40: 8
...

Sheet Аналитика
A1: Номер недели | B1: 8 | C1: =COUNTIF(RawData!D:D,CurSprint) -> 19
A3: Корреляции | B3: красное | C3: зеленое | D3: серое | E3: остаток | F3: Удовлетворенность неделей | G3: Похожесть недели | H3: Работа / личная жизнь
A4: Стресс | B4: =CORREL(RawData!F:F,RawData!$W:$W) -> 0.29999389 | C4: =CORREL(RawData!G:G,RawData!$W:$W) -> -0.38973709 | D4: =CORREL(RawData!H:H,RawData!$W:$W) -> -0.01280964 | E4: =CORREL(RawData!I:I,RawData!$W:$W) -> 0.076878179 | F4: =CORREL(RawData!J:J,RawData!$W:$W) -> -0.4602701 | G4: =CORREL(RawData!K:K,RawData!$W:$W) -> -0.3233229 | H4: =CORREL(RawData!L:L,RawData!$W:$W) -> 0.22043054
A5: Дистресс | B5: =CORREL(RawData!F:F,RawData!$U:$U) -> 0.24188091 | C5: =CORREL(RawData!G:G,RawData!$U:$U) -> -0.31804272 | D5: =CORREL(RawData!H:H,RawData!$U:$U) -> -0.021217448 | E5: =CORREL(RawData!I:I,RawData!$U:$U) -> 0.077723984 | F5: =CORREL(RawData!J:J,RawData!$U:$U) -> -0.34412419 | G5: =CORREL(RawData!K:K,RawData!$U:$U) -> -0.25267316 | H5: =CORREL(RawData!L:L,RawData!$U:$U) -> 0.19483804
A6: Совладание | B6: =CORREL(RawData!F:F,RawData!$V:$V) -> -0.29082283 | C6: =CORREL(RawData!G:G,RawData!$V:$V) -> 0.37332116 | D6: =CORREL(RawData!H:H,RawData!$V:$V) -> -0.00047036845 | E6: =CORREL(RawData!I:I,RawData!$V:$V) -> -0.055900339 | F6: =CORREL(RawData!J:J,RawData!$V:$V) -> 0.47813878 | G6: =CORREL(RawData!K:K,RawData!$V:$V) -> 0.32292825 | H6: =CORREL(RawData!L:L,RawData!$V:$V) -> -0.19344292
A7: Удовлетворенность неделей | B7: =CORREL(RawData!F:F,RawData!J:J) -> -0.25141069 | C7: =CORREL(RawData!G:G,RawData!J:J) -> 0.46529536
A10: Всего ответов | B10: =COUNTIF(RawData!D:D,B1) -> 19
B11: Красное | C11: Зеленое | D11: Серое
A12: 0 | B12: =COUNTIFS(RawData!F:F,$A12,RawData!$D:$D,$B$1)/TotalWeekRespondents -> 0.21052632 | C12: =COUNTIFS(RawData!G:G,$A12,RawData!$D:$D,$B$1)/TotalWeekRespondents -> 0.15789474 | D12: =COUNTIFS(RawData!H:H,$A12,RawData!$D:$D,$B$1)/TotalWeekRespondents -> 0.15789474
A13: 1 | B13: =COUNTIFS(RawData!F:F,$A13,RawData!$D:$D,$B$1)/TotalWeekRespondents -> 0.36842105 | C13: =COUNTIFS(RawData!G:G,$A13,RawData!$D:$D,$B$1)/TotalWeekRespondents -> 0.31578947 | D13: =COUNTIFS(RawData!H:H,$A13,RawData!$D:$D,$B$1)/TotalWeekRespondents -> 0.10526316
A14: 2 | B14: =COUNTIFS(RawData!F:F,$A14,RawData!$D:$D,$B$1)/TotalWeekRespondents -> 0.21052632 | C14: =COUNTIFS(RawData!G:G,$A14,RawData!$D:$D,$B$1)/TotalWeekRespondents -> 0.21052632 | D14: =COUNTIFS(RawData!H:H,$A14,RawData!$D:$D,$B$1)/TotalWeekRespondents -> 0.36842105
A15: 3 | B15: =COUNTIFS(RawData!F:F,$A15,RawData!$D:$D,$B$1)/TotalWeekRespondents -> 0.10526316 | C15: =COUNTIFS(RawData!G:G,$A15,RawData!$D:$D,$B$1)/TotalWeekRespondents -> 0.21052632 | D15: =COUNTIFS(RawData!H:H,$A15,RawData!$D:$D,$B$1)/TotalWeekRespondents -> 0.31578947
A16: 4 | B16: =COUNTIFS(RawData!F:F,$A16,RawData!$D:$D,$B$1)/TotalWeekRespondents -> 0 | C16: =COUNTIFS(RawData!G:G,$A16,RawData!$D:$D,$B$1)/TotalWeekRespondents -> 0.10526316 | D16: =COUNTIFS(RawData!H:H,$A16,RawData!$D:$D,$B$1)/TotalWeekRespondents -> 0
A17: 5 | B17: =COUNTIFS(RawData!F:F,$A17,RawData!$D:$D,$B$1)/TotalWeekRespondents -> 0 | C17: =COUNTIFS(RawData!G:G,$A17,RawData!$D:$D,$B$1)/TotalWeekRespondents -> 0 | D17: =COUNTIFS(RawData!H:H,$A17,RawData!$D:$D,$B$1)/TotalWeekRespondents -> 0
A18: 6 | B18: =COUNTIFS(RawData!F:F,$A18,RawData!$D:$D,$B$1)/TotalWeekRespondents -> 0.10526316 | C18: =COUNTIFS(RawData!G:G,$A18,RawData!$D:$D,$B$1)/TotalWeekRespondents -> 0 | D18: =COUNTIFS(RawData!H:H,$A18,RawData!$D:$D,$B$1)/TotalWeekRespondents -> 0.052631579
B21: Репрезентативность недели
A22: -3 | B22: Значительно хуже | C22: =COUNTIFS(RawData!K:K,A22,RawData!$D:$D,$B$1)/TotalWeekRespondents -> 0.052631579
A23: -2 | B23: Хуже | C23: =COUNTIFS(RawData!K:K,A23,RawData!$D:$D,$B$1)/TotalWeekRespondents -> 0.10526316
A24: -1 | B24: Чуть хуже | C24: =COUNTIFS(RawData!K:K,A24,RawData!$D:$D,$B$1)/TotalWeekRespondents -> 0.21052632
A25: 0 | B25: Как обычно | C25: =COUNTIFS(RawData!K:K,A25,RawData!$D:$D,$B$1)/TotalWeekRespondents -> 0.21052632
A26: 1 | B26: Чуть лучше | C26: =COUNTIFS(RawData!K:K,A26,RawData!$D:$D,$B$1)/TotalWeekRespondents -> 0.26315789
A27: 2 | B27: Лучше | C27: =COUNTIFS(RawData!K:K,A27,RawData!$D:$D,$B$1)/TotalWeekRespondents -> 0.15789474
A28: 3 | B28: Значительно лучше | C28: =COUNTIFS(RawData!K:K,A28,RawData!$D:$D,$B$1)/TotalWeekRespondents -> 0
B30: Личная жизнь или работа
A31: -3 | B31: Всё на личное | C31: =COUNTIFS(RawData!L:L,A31,RawData!$D:$D,$B$1)/TotalWeekRespondents -> 0.052631579
A32: -2 | C32: =COUNTIFS(RawData!L:L,A32,RawData!$D:$D,$B$1)/TotalWeekRespondents -> 0.052631579
A33: -1 | C33: =COUNTIFS(RawData!L:L,A33,RawData!$D:$D,$B$1)/TotalWeekRespondents -> 0.15789474
A34: 0 | B34: Баланс | C34: =COUNTIFS(RawData!L:L,A34,RawData!$D:$D,$B$1)/TotalWeekRespondents -> 0.26315789
A35: 1 | C35: =COUNTIFS(RawData!L:L,A35,RawData!$D:$D,$B$1)/TotalWeekRespondents -> 0.21052632
A36: 2 | C36: =COUNTIFS(RawData!L:L,A36,RawData!$D:$D,$B$1)/TotalWeekRespondents -> 0.10526316
A37: 3 | B37: Всё на работу | C37: =COUNTIFS(RawData!L:L,A37,RawData!$D:$D,$B$1)/TotalWeekRespondents -> 0.15789474
B40: На сколько я доволен неделей?
A41: 1 | B41: Фу, отстой :-( | C41: =COUNTIFS(RawData!J:J,A41,RawData!$D:$D,$B$1)/TotalWeekRespondents -> 0.052631579
A42: 2 | C42: =COUNTIFS(RawData!J:J,A42,RawData!$D:$D,$B$1)/TotalWeekRespondents -> 0.10526316
A43: 3 | C43: =COUNTIFS(RawData!J:J,A43,RawData!$D:$D,$B$1)/TotalWeekRespondents -> 0.15789474
A44: 4 | B44: Средненько | C44: =COUNTIFS(RawData!J:J,A44,RawData!$D:$D,$B$1)/TotalWeekRespondents -> 0.21052632
A45: 5 | C45: =COUNTIFS(RawData!J:J,A45,RawData!$D:$D,$B$1)/TotalWeekRespondents -> 0.21052632
A46: 6 | C46: =COUNTIFS(RawData!J:J,A46,RawData!$D:$D,$B$1)/TotalWeekRespondents -> 0.21052632
A47: 7 | B47: Я - молодец!!1 | C47: =COUNTIFS(RawData!J:J,A47,RawData!$D:$D,$B$1)/TotalWeekRespondents -> 0.052631579
B49: 0 | C49: 1 | D49: 2 | E49: 3 | F49: 4 | G49: 5 | H49: 6 | I49: 7 | J49: 8 | K49: 9 | L49: 10 | M49: 11 | N49: 12
...

Sheet По человекам
A2: Участник | B2: asya_in_motion
C3: Средний фактор дистресса | D3: Средний фактор совладания
A4: 0 | B4: Неделя 0 | C4: =IF(COUNTIFS(RawData!$D:$D,$A4,RawData!C:C, $B$2) > 0, (SUMIFS(RawData!$U:$U,RawData!$D:$D,$A4,RawData!C:C, $B$2))/(8*COUNTIFS(RawData!$D:$D,$A4,RawData!C:C, $B$2)),"") -> 0.625 | D4: =IF(COUNTIFS(RawData!$D:$D,$A4,RawData!C:C, $B$2) > 0, (SUMIFS(RawData!$V:$V,RawData!$D:$D,$A4,RawData!C:C, $B$2)/COUNTIFS(RawData!$D:$D,$A4,RawData!C:C, $B$2))/8,"") -> 0.5
A5: 1 | B5: Неделя 1 | C5: =IF(COUNTIFS(RawData!$D:$D,$A5,RawData!C:C, $B$2) > 0, (SUMIFS(RawData!$U:$U,RawData!$D:$D,$A5,RawData!C:C, $B$2))/(8*COUNTIFS(RawData!$D:$D,$A5,RawData!C:C, $B$2)),"") | D5: =IF(COUNTIFS(RawData!$D:$D,$A5,RawData!C:C, $B$2) > 0, (SUMIFS(RawData!$V:$V,RawData!$D:$D,$A5,RawData!C:C, $B$2)/COUNTIFS(RawData!$D:$D,$A5,RawData!C:C, $B$2))/8,"")
A6: 2 | B6: Неделя 2 | C6: =IF(COUNTIFS(RawData!$D:$D,$A6,RawData!C:C, $B$2) > 0, (SUMIFS(RawData!$U:$U,RawData!$D:$D,$A6,RawData!C:C, $B$2))/(8*COUNTIFS(RawData!$D:$D,$A6,RawData!C:C, $B$2)),"") -> 0.5 | D6: =IF(COUNTIFS(RawData!$D:$D,$A6,RawData!C:C, $B$2) > 0, (SUMIFS(RawData!$V:$V,RawData!$D:$D,$A6,RawData!C:C, $B$2)/COUNTIFS(RawData!$D:$D,$A6,RawData!C:C, $B$2))/8,"") -> 0.375
A7: 3 | B7: Неделя 3 | C7: =IF(COUNTIFS(RawData!$D:$D,$A7,RawData!C:C, $B$2) > 0, (SUMIFS(RawData!$U:$U,RawData!$D:$D,$A7,RawData!C:C, $B$2))/(8*COUNTIFS(RawData!$D:$D,$A7,RawData!C:C, $B$2)),"") -> 0.875 | D7: =IF(COUNTIFS(RawData!$D:$D,$A7,RawData!C:C, $B$2) > 0, (SUMIFS(RawData!$V:$V,RawData!$D:$D,$A7,RawData!C:C, $B$2)/COUNTIFS(RawData!$D:$D,$A7,RawData!C:C, $B$2))/8,"") -> 0.75
A8: 4 | B8: Неделя 4 | C8: =IF(COUNTIFS(RawData!$D:$D,$A8,RawData!C:C, $B$2) > 0, (SUMIFS(RawData!$U:$U,RawData!$D:$D,$A8,RawData!C:C, $B$2))/(8*COUNTIFS(RawData!$D:$D,$A8,RawData!C:C, $B$2)),"") -> 1 | D8: =IF(COUNTIFS(RawData!$D:$D,$A8,RawData!C:C, $B$2) > 0, (SUMIFS(RawData!$V:$V,RawData!$D:$D,$A8,RawData!C:C, $B$2)/COUNTIFS(RawData!$D:$D,$A8,RawData!C:C, $B$2))/8,"") -> 0.625
A9: 5 | B9: Неделя 5 | C9: =IF(COUNTIFS(RawData!$D:$D,$A9,RawData!C:C, $B$2) > 0, (SUMIFS(RawData!$U:$U,RawData!$D:$D,$A9,RawData!C:C, $B$2))/(8*COUNTIFS(RawData!$D:$D,$A9,RawData!C:C, $B$2)),"") | D9: =IF(COUNTIFS(RawData!$D:$D,$A9,RawData!C:C, $B$2) > 0, (SUMIFS(RawData!$V:$V,RawData!$D:$D,$A9,RawData!C:C, $B$2)/COUNTIFS(RawData!$D:$D,$A9,RawData!C:C, $B$2))/8,"")
A10: 6 | B10: Неделя 6 | C10: =IF(COUNTIFS(RawData!$D:$D,$A10,RawData!C:C, $B$2) > 0, (SUMIFS(RawData!$U:$U,RawData!$D:$D,$A10,RawData!C:C, $B$2))/(8*COUNTIFS(RawData!$D:$D,$A10,RawData!C:C, $B$2)),"") -> 0.625 | D10: =IF(COUNTIFS(RawData!$D:$D,$A10,RawData!C:C, $B$2) > 0, (SUMIFS(RawData!$V:$V,RawData!$D:$D,$A10,RawData!C:C, $B$2)/COUNTIFS(RawData!$D:$D,$A10,RawData!C:C, $B$2))/8,"") -> 0.4375
A11: 7 | B11: Неделя 7 | C11: =IF(COUNTIFS(RawData!$D:$D,$A11,RawData!C:C, $B$2) > 0, (SUMIFS(RawData!$U:$U,RawData!$D:$D,$A11,RawData!C:C, $B$2))/(8*COUNTIFS(RawData!$D:$D,$A11,RawData!C:C, $B$2)),"") | D11: =IF(COUNTIFS(RawData!$D:$D,$A11,RawData!C:C, $B$2) > 0, (SUMIFS(RawData!$V:$V,RawData!$D:$D,$A11,RawData!C:C, $B$2)/COUNTIFS(RawData!$D:$D,$A11,RawData!C:C, $B$2))/8,"")
A12: 8 | B12: Неделя 8 | C12: =IF(COUNTIFS(RawData!$D:$D,$A12,RawData!C:C, $B$2) > 0, (SUMIFS(RawData!$U:$U,RawData!$D:$D,$A12,RawData!C:C, $B$2))/(8*COUNTIFS(RawData!$D:$D,$A12,RawData!C:C, $B$2)),"") -> 0.5 | D12: =IF(COUNTIFS(RawData!$D:$D,$A12,RawData!C:C, $B$2) > 0, (SUMIFS(RawData!$V:$V,RawData!$D:$D,$A12,RawData!C:C, $B$2)/COUNTIFS(RawData!$D:$D,$A12,RawData!C:C, $B$2))/8,"") -> 0.5
A13: 9 | B13: Неделя 9 | C13: =IF(COUNTIFS(RawData!$D:$D,$A13,RawData!C:C, $B$2) > 0, (SUMIFS(RawData!$U:$U,RawData!$D:$D,$A13,RawData!C:C, $B$2))/(8*COUNTIFS(RawData!$D:$D,$A13,RawData!C:C, $B$2)),"") | D13: =IF(COUNTIFS(RawData!$D:$D,$A13,RawData!C:C, $B$2) > 0, (SUMIFS(RawData!$V:$V,RawData!$D:$D,$A13,RawData!C:C, $B$2)/COUNTIFS(RawData!$D:$D,$A13,RawData!C:C, $B$2))/8,"")
A14: 10 | B14: Неделя 10 | C14: =IF(COUNTIFS(RawData!$D:$D,$A14,RawData!C:C, $B$2) > 0, (SUMIFS(RawData!$U:$U,RawData!$D:$D,$A14,RawData!C:C, $B$2))/(8*COUNTIFS(RawData!$D:$D,$A14,RawData!C:C, $B$2)),"") | D14: =IF(COUNTIFS(RawData!$D:$D,$A14,RawData!C:C, $B$2) > 0, (SUMIFS(RawData!$V:$V,RawData!$D:$D,$A14,RawData!C:C, $B$2)/COUNTIFS(RawData!$D:$D,$A14,RawData!C:C, $B$2))/8,"")
A15: 11 | B15: Неделя 11 | C15: =IF(COUNTIFS(RawData!$D:$D,$A15,RawData!C:C, $B$2) > 0, (SUMIFS(RawData!$U:$U,RawData!$D:$D,$A15,RawData!C:C, $B$2))/(8*COUNTIFS(RawData!$D:$D,$A15,RawData!C:C, $B$2)),"") | D15: =IF(COUNTIFS(RawData!$D:$D,$A15,RawData!C:C, $B$2) > 0, (SUMIFS(RawData!$V:$V,RawData!$D:$D,$A15,RawData!C:C, $B$2)/COUNTIFS(RawData!$D:$D,$A15,RawData!C:C, $B$2))/8,"")
A16: 12 | B16: Неделя 12 | C16: =IF(COUNTIFS(RawData!$D:$D,$A16,RawData!C:C, $B$2) > 0, (SUMIFS(RawData!$U:$U,RawData!$D:$D,$A16,RawData!C:C, $B$2))/(8*COUNTIFS(RawData!$D:$D,$A16,RawData!C:C, $B$2)),"") | D16: =IF(COUNTIFS(RawData!$D:$D,$A16,RawData!C:C, $B$2) > 0, (SUMIFS(RawData!$V:$V,RawData!$D:$D,$A16,RawData!C:C, $B$2)/COUNTIFS(RawData!$D:$D,$A16,RawData!C:C, $B$2))/8,"")

Sheet Инсайты
A1: Инсайты
A2: =IFERROR(__xludf.DUMMYFUNCTION("ARRAYFORMULA(FILTER(RawData!Q2:Q1000,RawData!Q2:Q1000<>"""",RawData!D2:D1000=CurSprint) & char(10))"),"Улитка - сила. Пока необузданная сила ") -> Улитка - сила. Пока необузданная сила
A3: =IFERROR(__xludf.DUMMYFUNCTION("""COMPUTED_VALUE"""),"Все преодолимо, когда у тебя есть цель ") -> Все преодолимо, когда у тебя есть цель
A4: =IFERROR(__xludf.DUMMYFUNCTION("""COMPUTED_VALUE"""),"Вести личные и рабочие задачи в одном списке но не могу это делать на выходных ") -> Вести личные и рабочие задачи в одном списке но не могу это делать на выходных

Sheet Комментарии
A1: Комментарии
A2: =IFERROR(__xludf.DUMMYFUNCTION("ARRAYFORMULA(FILTER(RawData!R2:R1000,RawData!R2:R1000<>"""",RawData!D2:D1000=CurSprint) & char(10))"),"Вы красаффчики ") -> Вы красаффчики
